Workbook
Name evaluation_resultsft21SGD2.pt: ft21SGD!$A$1:$O$41
Name merged_feval_pilot_test: pilot_test!$A$1:$E$57
Name merged_feval_rzeszow_test: rzeszow_test!$A$1:$E$56
Name merged_feval_rzeszow_train: rzeszow_train!$A$1:$E$56
Name merged_feval_rzeszow_val: rzeszow_val!$A$1:$E$56
Name merged_feval_synth_new2_test: synth_new2_test!$A$1:$E$56
Name merged_feval_synth_new2_train: synth_new2_train!$A$1:$E$56
Name merged_feval_synth_new2_val: synth_new2_val!$A$1:$E$56
Name merged_feval_synth_old_test: synth_old_test!$A$1:$E$57
Name merged_feval_synth_old_train: synth_old_train!$A$1:$E$57
Name merged_feval_synth_old_val: synth_old_val!$A$1:$E$57

Sheet synth_new2_test
A1: setting | B1: Box-F1 | C1: mAP50 | D1: mAP50-95 | E1: Mask-F1 | F1: msc
A2: ft21_AdamW_feval.csv | B2: 0.995 | C2: 0.995 | D2: 0.834 | E2: 0.995 | F2: 1
A3: ft22_AdamW_feval.csv | B3: 0.995 | C3: 0.995 | D3: 0.809 | E3: 0.995 | F3: 2
A4: ft10_AdamW_feval.csv | B4: 0.995 | C4: 0.995 | D4: 0.799 | E4: 0.995 | F4: 3
A5: ft24_AdamW_feval.csv | B5: 0.995 | C5: 0.995 | D5: 0.793 | E5: 0.995 | F5: 4
A6: ft20_AdamW_feval.csv | B6: 0.995 | C6: 0.995 | D6: 0.791 | E6: 0.995 | F6: 5
A7: ft7_feval_AdamW.csv | B7: 0.995 | C7: 0.995 | D7: 0.788 | E7: 0.995 | F7: 6
A8: ft12c_AdamW_feval.csv | B8: 0.995 | C8: 0.995 | D8: 0.78 | E8: 0.995 | F8: 7
A9: ft12b_AdamW_feval.csv | B9: 0.995 | C9: 0.995 | D9: 0.774 | E9: 0.995 | F9: 8
A10: ft23_AdamW_feval.csv | B10: 0.991 | C10: 0.995 | D10: 0.773 | E10: 0.991 | F10: 9
A11: ft8_feval_AdamW.csv | B11: 0.995 | C11: 0.995 | D11: 0.77 | E11: 0.995 | F11: 10
A12: ft7_feval_auto.csv | B12: 0.986 | C12: 0.995 | D12: 0.763 | E12: 0.986 | F12: 11
A13: ft8_feval_auto.csv | B13: 0.986 | C13: 0.995 | D13: 0.763 | E13: 0.986 | F13: 12
... A56: ft24_RMSProp_feval.csv | B56: 0 | C56: 0 | D56: 0 | E56: 0 | F56: 55

Sheet synth_old_test
A1: setting | B1: Box-F1 | C1: mAP50 | D1: mAP50-95 | E1: Mask-F1 | F1: msc
A2: ft21_SGD_feval.csv | B2: 0.454 | C2: 0.379 | D2: 0.19 | E2: 0.332 | F2: 1
A3: ft12b_SGD_feval.csv | B3: 0.386 | C3: 0.359 | D3: 0.184 | E3: 0.224 | F3: 2
A4: ft25_SGD_feval.csv | B4: 0.34 | C4: 0.322 | D4: 0.181 | E4: 0.202 | F4: 3
A5: ft24_SGD_feval.csv | B5: 0.369 | C5: 0.32 | D5: 0.177 | E5: 0.232 | F5: 4
A6: ft9_feval_SGD.csv | B6: 0.365 | C6: 0.346 | D6: 0.172 | E6: 0.244 | F6: 5
A7: ft11_SGD_feval.csv | B7: 0.397 | C7: 0.337 | D7: 0.164 | E7: 0.233 | F7: 6
A8: ft23_SGD_feval.csv | B8: 0.393 | C8: 0.311 | D8: 0.16 | E8: 0.287 | F8: 7
A9: ft25_SGD_ariel.pt_feval.csv | B9: 0.383 | C9: 0.3 | D9: 0.159 | E9: 0 | F9: 8
A10: ft12c_SGD_feval.csv | B10: 0.352 | C10: 0.31 | D10: 0.157 | E10: 0.233 | F10: 9
A11: ft12_SGD_feval.csv | B11: 0.377 | C11: 0.312 | D11: 0.153 | E11: 0.219 | F11: 10
A12: ft8_feval_SGD.csv | B12: 0.33 | C12: 0.301 | D12: 0.15 | E12: 0.194 | F12: 11
A13: ft4_feval_SGD.csv | B13: 0.422 | C13: 0.338 | D13: 0.141 | E13: 0.188 | F13: 12
... A57: ft24_RMSProp_feval.csv | B57: 0 | C57: 0 | D57: 0 | E57: 0 | F57: 56

Sheet synth_old_train
A1: setting | B1: Box-F1 | C1: mAP50 | D1: mAP50-95 | E1: Mask-F1 | F1: msc
A2: ft25_SGD_ariel.pt_feval.csv | B2: 0.493 | C2: 0.423 | D2: 0.21 | E2: 0 | F2: 1
A3: ft24_SGD_ariel.pt_feval.csv | B3: 0.464 | C3: 0.394 | D3: 0.187 | E3: 0 | F3: 2
A4: ft23_SGD_ariel.pt_feval.csv | B4: 0.446 | C4: 0.376 | D4: 0.161 | E4: 0 | F4: 3
A5: ft25_AdamW_ariel.pt_feval.csv | B5: 0.443 | C5: 0.349 | D5: 0.158 | E5: 0 | F5: 4
A6: ft21_SGD_ariel.pt_feval.csv | B6: 0.434 | C6: 0.351 | D6: 0.156 | E6: 0 | F6: 5
A7: ft20_SGD_ariel.pt_feval.csv | B7: 0.429 | C7: 0.342 | D7: 0.153 | E7: 0 | F7: 6
A8: ft24_AdamW_ariel.pt_feval.csv | B8: 0.426 | C8: 0.333 | D8: 0.152 | E8: 0 | F8: 7
A9: ft22_SGD_ariel.pt_feval.csv | B9: 0.424 | C9: 0.335 | D9: 0.148 | E9: 0 | F9: 8
A10: ft23_AdamW_ariel.pt_feval.csv | B10: 0.417 | C10: 0.318 | D10: 0.142 | E10: 0 | F10: 9
A11: ft25_SGD_feval.csv | B11: 0.355 | C11: 0.278 | D11: 0.137 | E11: 0.293 | F11: 10
A12: ft21_SGD_feval.csv | B12: 0.342 | C12: 0.276 | D12: 0.134 | E12: 0.297 | F12: 11
A13: ft24_SGD_feval.csv | B13: 0.354 | C13: 0.281 | D13: 0.134 | E13: 0.294 | F13: 12
... A57: ft24_RMSProp_feval.csv | B57: 0 | C57: 0 | D57: 0 | E57: 0 | F57: 56

Sheet synth_old_val
A1: setting | B1: Box-F1 | C1: mAP50 | D1: mAP50-95 | E1: Mask-F1 | F1: msc
A2: ft10_SGD_feval.csv | B2: 0.661 | C2: 0.693 | D2: 0.375 | E2: 0.578 | F2: 1
A3: ft21_SGD_feval.csv | B3: 0.687 | C3: 0.674 | D3: 0.355 | E3: 0.622 | F3: 2
A4: ft8_feval_SGD.csv | B4: 0.664 | C4: 0.671 | D4: 0.346 | E4: 0.6 | F4: 3
A5: ft23_SGD_feval.csv | B5: 0.744 | C5: 0.743 | D5: 0.339 | E5: 0.681 | F5: 4
A6: ft21_AdamW_feval.csv | B6: 0.596 | C6: 0.604 | D6: 0.335 | E6: 0.544 | F6: 5
A7: ft25_SGD_ariel.pt_feval.csv | B7: 0.653 | C7: 0.634 | D7: 0.333 | E7: 0 | F7: 6
A8: ft24_SGD_ariel.pt_feval.csv | B8: 0.618 | C8: 0.613 | D8: 0.312 | E8: 0 | F8: 7
A9: ft22_SGD_feval.csv | B9: 0.654 | C9: 0.664 | D9: 0.311 | E9: 0.594 | F9: 8
A10: ft25_SGD_feval.csv | B10: 0.582 | C10: 0.601 | D10: 0.31 | E10: 0.53 | F10: 9
A11: ft12b_SGD_feval.csv | B11: 0.639 | C11: 0.62 | D11: 0.305 | E11: 0.556 | F11: 10
A12: ft24_SGD_feval.csv | B12: 0.545 | C12: 0.604 | D12: 0.304 | E12: 0.483 | F12: 11
A13: ft23_SGD_ariel.pt_feval.csv | B13: 0.664 | C13: 0.646 | D13: 0.303 | E13: 0 | F13: 12
... A57: ft24_RMSProp_feval.csv | B57: 0 | C57: 0 | D57: 0 | E57: 0 | F57: 56

Sheet pilot_test
A1: setting | B1: Box-F1 | C1: mAP50 | D1: mAP50-95 | E1: Mask-F1 | F1: msc
A2: ft25_AdamW_ariel.pt_feval.csv | B2: 0.306 | C2: 0.255 | D2: 0.107 | E2: 0 | F2: 1
A3: ft24_SGD_ariel.pt_feval.csv | B3: 0.345 | C3: 0.262 | D3: 0.105 | E3: 0 | F3: 2
A4: ft25_SGD_ariel.pt_feval.csv | B4: 0.348 | C4: 0.256 | D4: 0.101 | E4: 0 | F4: 3
A5: ft24_AdamW_ariel.pt_feval.csv | B5: 0.296 | C5: 0.24 | D5: 0.089 | E5: 0 | F5: 4
A6: ft11_SGD_feval.csv | B6: 0.186 | C6: 0.154 | D6: 0.074 | E6: 0.164 | F6: 5
A7: ft12_SGD_feval.csv | B7: 0.192 | C7: 0.152 | D7: 0.071 | E7: 0.173 | F7: 6
A8: ft21_AdamW_ariel.pt_feval.csv | B8: 0.253 | C8: 0.182 | D8: 0.07 | E8: 0 | F8: 7
A9: ft9_feval_SGD.csv | B9: 0.213 | C9: 0.151 | D9: 0.068 | E9: 0.173 | F9: 8
A10: ft12b_SGD_feval.csv | B10: 0.212 | C10: 0.147 | D10: 0.067 | E10: 0.178 | F10: 9
A11: ft20_AdamW_ariel.pt_feval.csv | B11: 0.283 | C11: 0.178 | D11: 0.067 | E11: 0 | F11: 10
A12: ft23_AdamW_ariel.pt_feval.csv | B12: 0.274 | C12: 0.197 | D12: 0.066 | E12: 0 | F12: 11
A13: ft12c_SGD_feval.csv | B13: 0.219 | C13: 0.137 | D13: 0.064 | E13: 0.191 | F13: 12
... A57: ft24_RMSProp_feval.csv | B57: 0 | C57: 0 | D57: 0 | E57: 0 | F57: 56

Sheet rzeszow_test
A1: setting | B1: Box-F1 | C1: mAP50 | D1: mAP50-95 | E1: Mask-F1 | F1: msc
A2: ft25_SGD_ariel.pt_feval.csv | B2: 0.81 | C2: 0.849 | D2: 0.514 | E2: 0 | F2: 1
A3: ft22_SGD_ariel.pt_feval.csv | B3: 0.815 | C3: 0.846 | D3: 0.508 | E3: 0 | F3: 2
A4: ft20_SGD_ariel.pt_feval.csv | B4: 0.813 | C4: 0.845 | D4: 0.506 | E4: 0 | F4: 3
A5: ft21_SGD_ariel.pt_feval.csv | B5: 0.812 | C5: 0.847 | D5: 0.506 | E5: 0 | F5: 4
A6: ft23_SGD_ariel.pt_feval.csv | B6: 0.811 | C6: 0.847 | D6: 0.504 | E6: 0 | F6: 5
A7: ft24_SGD_ariel.pt_feval.csv | B7: 0.796 | C7: 0.836 | D7: 0.499 | E7: 0 | F7: 6
A8: ft23_AdamW_ariel.pt_feval.csv | B8: 0.777 | C8: 0.803 | D8: 0.483 | E8: 0 | F8: 7
A9: ft24_AdamW_ariel.pt_feval.csv | B9: 0.775 | C9: 0.808 | D9: 0.479 | E9: 0 | F9: 8
A10: ft25_AdamW_ariel.pt_feval.csv | B10: 0.761 | C10: 0.791 | D10: 0.468 | E10: 0 | F10: 9
A11: ft21_AdamW_ariel.pt_feval.csv | B11: 0.752 | C11: 0.774 | D11: 0.461 | E11: 0 | F11: 10
A12: ft20_AdamW_ariel.pt_feval.csv | B12: 0.738 | C12: 0.756 | D12: 0.445 | E12: 0 | F12: 11
A13: ft22_AdamW_ariel.pt_feval.csv | B13: 0.744 | C13: 0.762 | D13: 0.444 | E13: 0 | F13: 12
... A56: ft24_RMSProp_feval.csv | B56: 0 | C56: 0 | D56: 0 | E56: 0 | F56: 55

Sheet rzeszow_train
A1: setting | B1: Box-F1 | C1: mAP50 | D1: mAP50-95 | E1: Mask-F1 | F1: msc
A2: ft25_AdamW_feval.csv | B2: 0.877 | C2: 0.928 | D2: 0.709 | E2: 0.855 | F2: 1
A3: ft22_SGD_feval.csv | B3: 0.88 | C3: 0.924 | D3: 0.7 | E3: 0.853 | F3: 2
A4: ft20_SGD_feval.csv | B4: 0.884 | C4: 0.925 | D4: 0.696 | E4: 0.855 | F4: 3
A5: ft21_SGD_feval.csv | B5: 0.872 | C5: 0.917 | D5: 0.687 | E5: 0.839 | F5: 4
A6: ft24_AdamW_feval.csv | B6: 0.844 | C6: 0.894 | D6: 0.667 | E6: 0.814 | F6: 5
A7: ft23_SGD_feval.csv | B7: 0.848 | C7: 0.894 | D7: 0.661 | E7: 0.818 | F7: 6
A8: ft23_AdamW_ariel.pt_feval.csv | B8: 0.876 | C8: 0.915 | D8: 0.66 | E8: 0 | F8: 7
A9: ft21_AdamW_ariel.pt_feval.csv | B9: 0.864 | C9: 0.916 | D9: 0.655 | E9: 0 | F9: 8
A10: ft22_AdamW_ariel.pt_feval.csv | B10: 0.879 | C10: 0.912 | D10: 0.655 | E10: 0 | F10: 9
A11: ft20_AdamW_ariel.pt_feval.csv | B11: 0.875 | C11: 0.914 | D11: 0.65 | E11: 0 | F11: 10
A12: ft22_SGD_ariel.pt_feval.csv | B12: 0.859 | C12: 0.888 | D12: 0.629 | E12: 0 | F12: 11
A13: ft20_SGD_ariel.pt_feval.csv | B13: 0.857 | C13: 0.891 | D13: 0.625 | E13: 0 | F13: 12
... A56: ft24_RMSProp_feval.csv | B56: 0 | C56: 0 | D56: 0 | E56: 0 | F56: 55

Sheet rzeszow_val
A1: setting | B1: Box-F1 | C1: mAP50 | D1: mAP50-95 | E1: Mask-F1 | F1: msc
A2: ft12c_AdamW_feval.csv | B2: 0.85 | C2: 0.855 | D2: 0.67 | E2: 0.842 | F2: 1
A3: ft12_AdamW_feval.csv | B3: 0.846 | C3: 0.848 | D3: 0.657 | E3: 0.833 | F3: 2
A4: ft12b_AdamW_feval.csv | B4: 0.837 | C4: 0.842 | D4: 0.651 | E4: 0.821 | F4: 3
A5: ft10_SGD_feval.csv | B5: 0.823 | C5: 0.823 | D5: 0.624 | E5: 0.81 | F5: 4
A6: ft7_feval_SGD.csv | B6: 0.818 | C6: 0.826 | D6: 0.624 | E6: 0.805 | F6: 5
A7: ft11_AdamW_feval.csv | B7: 0.816 | C7: 0.819 | D7: 0.62 | E7: 0.797 | F7: 6
A8: ft10_AdamW_feval.csv | B8: 0.801 | C8: 0.805 | D8: 0.598 | E8: 0.761 | F8: 7
A9: ft8_feval_SGD.csv | B9: 0.791 | C9: 0.794 | D9: 0.587 | E9: 0.781 | F9: 8
A10: ft9_feval_AdamW.csv | B10: 0.796 | C10: 0.791 | D10: 0.583 | E10: 0.774 | F10: 9
A11: ft8_feval_AdamW.csv | B11: 0.768 | C11: 0.769 | D11: 0.555 | E11: 0.721 | F11: 10
A12: ft12_SGD_feval.csv | B12: 0.754 | C12: 0.748 | D12: 0.544 | E12: 0.746 | F12: 11
A13: ft11_SGD_feval.csv | B13: 0.706 | C13: 0.693 | D13: 0.496 | E13: 0.692 | F13: 12
... A56: ft24_RMSProp_feval.csv | B56: 0 | C56: 0 | D56: 0 | E56: 0 | F56: 55

Sheet top5s
A1: setting | B1: Box-F1 | C1: mAP50 | D1: mAP50-95 | E1: Mask-F1 | H1: Etykiety wierszy | I1: Licznik z setting
A2: ft21_AdamW_feval.csv | B2: 0.995 | C2: 0.995 | D2: 0.834 | E2: 0.995 | H2: ft21_SGD_feval.csv | I2: 3
A3: ft22_AdamW_feval.csv | B3: 0.995 | C3: 0.995 | D3: 0.809 | E3: 0.995 | H3: ft25_SGD_ariel.pt_feval.csv | I3: 3
A4: ft10_AdamW_feval.csv | B4: 0.995 | C4: 0.995 | D4: 0.799 | E4: 0.995 | H4: ft24_AdamW_feval.csv | I4: 2
A5: ft24_AdamW_feval.csv | B5: 0.995 | C5: 0.995 | D5: 0.793 | E5: 0.995 | H5: ft21_AdamW_feval.csv | I5: 2
A6: ft20_AdamW_feval.csv | B6: 0.995 | C6: 0.995 | D6: 0.791 | E6: 0.995 | H6: ft24_SGD_ariel.pt_feval.csv | I6: 2
A7: ft21_SGD_feval.csv | B7: 0.454 | C7: 0.379 | D7: 0.19 | E7: 0.332 | H7: ft25_AdamW_ariel.pt_feval.csv | I7: 2
A8: ft12b_SGD_feval.csv | B8: 0.386 | C8: 0.359 | D8: 0.184 | E8: 0.224 | H8: ft10_SGD_feval.csv | I8: 2
A9: ft25_SGD_feval.csv | B9: 0.34 | C9: 0.322 | D9: 0.181 | E9: 0.202 | H9: ft21_SGD_ariel.pt_feval.csv | I9: 2
A10: ft24_SGD_feval.csv | B10: 0.369 | C10: 0.32 | D10: 0.177 | E10: 0.232 | H10: ft23_SGD_ariel.pt_feval.csv | I10: 2
A11: ft9_feval_SGD.csv | B11: 0.365 | C11: 0.346 | D11: 0.172 | E11: 0.244 | H11: ft9_feval_SGD.csv | I11: 1
A12: ft25_SGD_ariel.pt_feval.csv | B12: 0.493 | C12: 0.423 | D12: 0.21 | E12: 0 | H12: ft25_AdamW_feval.csv | I12: 1
A13: ft24_SGD_ariel.pt_feval.csv | B13: 0.464 | C13: 0.394 | D13: 0.187 | E13: 0 | H13: ft20_AdamW_feval.csv | I13: 1
... A31: ft23_SGD_ariel.pt_feval.csv | B31: 0.811 | C31: 0.847 | D31: 0.504 | E31: 0 | H31: Suma końcowa | I31: 40
A32: ft25_AdamW_feval.csv | B32: 0.877 | C32: 0.928 | D32: 0.709 | E32: 0.855
A33: ft22_SGD_feval.csv | B33: 0.88 | C33: 0.924 | D33: 0.7 | E33: 0.853
A34: ft20_SGD_feval.csv | B34: 0.884 | C34: 0.925 | D34: 0.696 | E34: 0.855
A35: ft21_SGD_feval.csv | B35: 0.872 | C35: 0.917 | D35: 0.687 | E35: 0.839
A36: ft24_AdamW_feval.csv | B36: 0.844 | C36: 0.894 | D36: 0.667 | E36: 0.814
A37: ft12c_AdamW_feval.csv | B37: 0.85 | C37: 0.855 | D37: 0.67 | E37: 0.842
A38: ft12_AdamW_feval.csv | B38: 0.846 | C38: 0.848 | D38: 0.657 | E38: 0.833
A39: ft12b_AdamW_feval.csv | B39: 0.837 | C39: 0.842 | D39: 0.651 | E39: 0.821
A40: ft10_SGD_feval.csv | B40: 0.823 | C40: 0.823 | D40: 0.624 | E40: 0.81
A41: ft7_feval_SGD.csv | B41: 0.818 | C41: 0.826 | D41: 0.624 | E41: 0.805

Sheet Smsc
A1: =synth_old_test!A1 -> setting | B1: =synth_old_test!F1 -> msc | E1: Etykiety wierszy | F1: Suma z msc
A2: =synth_old_test!A2 -> ft21_SGD_feval.csv | B2: =synth_old_test!F2 -> 1 | E2: ft25_SGD_ariel.pt_feval.csv | F2: 57
A3: =synth_old_test!A3 -> ft12b_SGD_feval.csv | B3: =synth_old_test!F3 -> 2 | E3: ft24_SGD_ariel.pt_feval.csv | F3: 75
A4: =synth_old_test!A4 -> ft25_SGD_feval.csv | B4: =synth_old_test!F4 -> 3 | E4: ft23_SGD_ariel.pt_feval.csv | F4: 94
A5: =synth_old_test!A5 -> ft24_SGD_feval.csv | B5: =synth_old_test!F5 -> 4 | E5: ft4_feval_SGD.csv | F5: 94
A6: =synth_old_test!A6 -> ft9_feval_SGD.csv | B6: =synth_old_test!F6 -> 5 | E6: ft21_SGD_ariel.pt_feval.csv | F6: 105
A7: =synth_old_test!A7 -> ft11_SGD_feval.csv | B7: =synth_old_test!F7 -> 6 | E7: ft12b_SGD_feval.csv | F7: 110
A8: =synth_old_test!A8 -> ft23_SGD_feval.csv | B8: =synth_old_test!F8 -> 7 | E8: ft21_SGD_feval.csv | F8: 114
A9: =synth_old_test!A9 -> ft25_SGD_ariel.pt_feval.csv | B9: =synth_old_test!F9 -> 8 | E9: ft20_SGD_ariel.pt_feval.csv | F9: 115
A10: =synth_old_test!A10 -> ft12c_SGD_feval.csv | B10: =synth_old_test!F10 -> 9 | E10: ft22_SGD_ariel.pt_feval.csv | F10: 115
A11: =synth_old_test!A11 -> ft12_SGD_feval.csv | B11: =synth_old_test!F11 -> 10 | E11: ft23_AdamW_ariel.pt_feval.csv | F11: 116
A12: =synth_old_test!A12 -> ft8_feval_SGD.csv | B12: =synth_old_test!F12 -> 11 | E12: ft25_AdamW_ariel.pt_feval.csv | F12: 116
A13: =synth_old_test!A13 -> ft4_feval_SGD.csv | B13: =synth_old_test!F13 -> 12 | E13: ft10_SGD_feval.csv | F13: 117
... A57: =synth_old_test!A57 -> ft24_RMSProp_feval.csv | B57: =synth_old_test!F57 -> 56 | E57: ft24_RMSProp_feval.csv | F57: 389
A58: =synth_old_train!A2 -> ft25_SGD_ariel.pt_feval.csv | B58: =synth_old_train!F2 -> 1 | E58: Suma końcowa | F58: 11004
A59: =synth_old_train!A3 -> ft24_SGD_ariel.pt_feval.csv | B59: =synth_old_train!F3 -> 2
A60: =synth_old_train!A4 -> ft23_SGD_ariel.pt_feval.csv | B60: =synth_old_train!F4 -> 3
A61: =synth_old_train!A5 -> ft25_AdamW_ariel.pt_feval.csv | B61: =synth_old_train!F5 -> 4
A62: =synth_old_train!A6 -> ft21_SGD_ariel.pt_feval.csv | B62: =synth_old_train!F6 -> 5
A63: =synth_old_train!A7 -> ft20_SGD_ariel.pt_feval.csv | B63: =synth_old_train!F7 -> 6
A64: =synth_old_train!A8 -> ft24_AdamW_ariel.pt_feval.csv | B64: =synth_old_train!F8 -> 7
A65: =synth_old_train!A9 -> ft22_SGD_ariel.pt_feval.csv | B65: =synth_old_train!F9 -> 8
A66: =synth_old_train!A10 -> ft23_AdamW_ariel.pt_feval.csv | B66: =synth_old_train!F10 -> 9
A67: =synth_old_train!A11 -> ft25_SGD_feval.csv | B67: =synth_old_train!F11 -> 10
A68: =synth_old_train!A12 -> ft21_SGD_feval.csv | B68: =synth_old_train!F12 -> 11
A69: =synth_old_train!A13 -> ft24_SGD_feval.csv | B69: =synth_old_train!F13 -> 12
A70: =synth_old_train!A14 -> ft12b_SGD_feval.csv | B70: =synth_old_train!F14 -> 13
... A113: =synth_old_train!A57 -> ft24_RMSProp_feval.csv | B113: =synth_old_train!F57 -> 56
A114: =synth_old_val!A2 -> ft10_SGD_feval.csv | B114: =synth_old_val!F2 -> 1
A115: =synth_old_val!A3 -> ft21_SGD_feval.csv | B115: =synth_old_val!F3 -> 2
A116: =synth_old_val!A4 -> ft8_feval_SGD.csv | B116: =synth_old_val!F4 -> 3
A117: =synth_old_val!A5 -> ft23_SGD_feval.csv | B117: =synth_old_val!F5 -> 4
A118: =synth_old_val!A6 -> ft21_AdamW_feval.csv | B118: =synth_old_val!F6 -> 5
A119: =synth_old_val!A7 -> ft25_SGD_ariel.pt_feval.csv | B119: =synth_old_val!F7 -> 6
A120: =synth_old_val!A8 -> ft24_SGD_ariel.pt_feval.csv | B120: =synth_old_val!F8 -> 7
A121: =synth_old_val!A9 -> ft22_SGD_feval.csv | B121: =synth_old_val!F9 -> 8
A122: =synth_old_val!A10 -> ft25_SGD_feval.csv | B122: =synth_old_val!F10 -> 9
A123: =synth_old_val!A11 -> ft12b_SGD_feval.csv | B123: =synth_old_val!F11 -> 10
A124: =synth_old_val!A12 -> ft24_SGD_feval.csv | B124: =synth_old_val!F12 -> 11
A125: =synth_old_val!A13 -> ft23_SGD_ariel.pt_feval.csv | B125: =synth_old_val!F13 -> 12
...

Sheet synth_new2_val
A1: setting | B1: Box-F1 | C1: mAP50 | D1: mAP50-95 | E1: Mask-F1
A2: ft24_AdamW_feval.csv | B2: 1 | C2: 0.995 | D2: 0.928 | E2: 1
A3: ft20_SGD_feval.csv | B3: 0.997 | C3: 0.995 | D3: 0.92 | E3: 0.997
A4: ft22_SGD_feval.csv | B4: 1 | C4: 0.995 | D4: 0.918 | E4: 1
A5: ft21_SGD_feval.csv | B5: 1 | C5: 0.995 | D5: 0.915 | E5: 1
A6: ft12c_AdamW_feval.csv | B6: 0.999 | C6: 0.995 | D6: 0.914 | E6: 0.999
A7: ft25_AdamW_feval.csv | B7: 1 | C7: 0.995 | D7: 0.912 | E7: 1
A8: ft12b_AdamW_feval.csv | B8: 1 | C8: 0.995 | D8: 0.91 | E8: 1
A9: ft21_AdamW_feval.csv | B9: 0.997 | C9: 0.995 | D9: 0.908 | E9: 0.997
A10: ft23_SGD_feval.csv | B10: 0.999 | C10: 0.995 | D10: 0.905 | E10: 0.999
A11: ft11_AdamW_feval.csv | B11: 1 | C11: 0.995 | D11: 0.897 | E11: 1
A12: ft9_feval_AdamW.csv | B12: 0.999 | C12: 0.995 | D12: 0.897 | E12: 0.999
A13: ft23_AdamW_feval.csv | B13: 1 | C13: 0.995 | D13: 0.894 | E13: 1
... A56: ft24_RMSProp_feval.csv | B56: 0 | C56: 0 | D56: 0 | E56: 0

Sheet synth_new2_train
A1: setting | B1: Box-F1 | C1: mAP50 | D1: mAP50-95 | E1: Mask-F1
A2: ft24_AdamW_feval.csv | B2: 0.997 | C2: 0.995 | D2: 0.924 | E2: 0.997
A3: ft12b_AdamW_feval.csv | B3: 0.995 | C3: 0.995 | D3: 0.921 | E3: 0.994
A4: ft25_AdamW_feval.csv | B4: 0.995 | C4: 0.995 | D4: 0.917 | E4: 0.994
A5: ft21_SGD_feval.csv | B5: 0.995 | C5: 0.995 | D5: 0.914 | E5: 0.995
A6: ft11_AdamW_feval.csv | B6: 0.993 | C6: 0.995 | D6: 0.913 | E6: 0.993
A7: ft12c_AdamW_feval.csv | B7: 0.995 | C7: 0.995 | D7: 0.912 | E7: 0.995
A8: ft22_SGD_feval.csv | B8: 0.997 | C8: 0.995 | D8: 0.912 | E8: 0.997
A9: ft12_AdamW_feval.csv | B9: 0.995 | C9: 0.995 | D9: 0.91 | E9: 0.994
A10: ft10_AdamW_feval.csv | B10: 0.995 | C10: 0.995 | D10: 0.909 | E10: 0.994
A11: ft20_SGD_feval.csv | B11: 0.996 | C11: 0.995 | D11: 0.909 | E11: 0.996
A12: ft21_AdamW_feval.csv | B12: 0.994 | C12: 0.995 | D12: 0.908 | E12: 0.994
A13: ft9_feval_AdamW.csv | B13: 0.995 | C13: 0.995 | D13: 0.908 | E13: 0.995
... A56: ft24_RMSProp_feval.csv | B56: 0 | C56: 0 | D56: 0 | E56: 0

Sheet ft21SGD
A1: dataset | B1: split | C1: model | D1: Class | E1: Images | F1: Instances | G1: Box-P | H1: Box-R | I1: Box-F1 | J1: mAP50 | K1: mAP50-95 | L1: Mask-P | M1: Mask-R | N1: Mask-F1 | O1: t
A2: pilot | B2: val | C2: finloop | D2: solar-panel | E2: 54 | F2: 227 | G2: 0.547 | H2: 0.414 | I2: 0.471 | J2: 0.379 | K2: 0.202 | L2: 0.202 | M2: 0.159 | N2: 0.178 | O2: 13.5146
A3: pilot | B3: val | C3: ft21SGD | D3: pv | E3: 54 | F3: 227 | G3: 0.277 | H3: 0.139 | I3: 0.185 | J3: 0.121 | K3: 0.049 | L3: 0.216 | M3: 0.11 | N3: 0.146 | O3: 5.5479817
A4: pilot | B4: val | C4: ariel | D4: solar-panel | E4: 54 | F4: 227 | G4: 0.546 | H4: 0.429 | I4: 0.481 | J4: 0.401 | K4: 0.206 | L4: 0 | M4: 0 | N4: 0 | O4: 3.6959569
A5: pilot | B5: val | C5: pools | D5: solarpanel | E5: 54 | F5: 227 | G5: 0.657 | H5: 0.523 | I5: 0.583 | J5: 0.553 | K5: 0.334 | L5: 0 | M5: 0 | N5: 0 | O5: 4.9389865
A6: rzeszow | B6: train | C6: finloop | D6: solar-panel | E6: 8440 | F6: 66301 | G6: 0.963 | H6: 0.929 | I6: 0.946 | J6: 0.961 | K6: 0.642 | L6: 0.936 | M6: 0.871 | N6: 0.902 | O6: 296.13215
A7: rzeszow | B7: train | C7: ft21SGD | D7: pv | E7: 8440 | F7: 66301 | G7: 0.637 | H7: 0.421 | I7: 0.507 | J7: 0.445 | K7: 0.264 | L7: 0.621 | M7: 0.407 | N7: 0.492 | O7: 69.74672
A8: rzeszow | B8: train | C8: ariel | D8: solar-panel | E8: 8440 | F8: 66301 | G8: 0.916 | H8: 0.843 | I8: 0.878 | J8: 0.905 | K8: 0.554 | L8: 0 | M8: 0 | N8: 0 | O8: 36.588187
A9: rzeszow | B9: train | C9: pools | D9: solarpanel | E9: 8440 | F9: 66301 | G9: 0.628 | H9: 0.397 | I9: 0.487 | J9: 0.446 | K9: 0.273 | L9: 0 | M9: 0 | N9: 0 | O9: 94.233101
A10: rzeszow | B10: val | C10: finloop | D10: solar-panel | E10: 661 | F10: 2767 | G10: 0.896 | H10: 0.786 | I10: 0.837 | J10: 0.824 | K10: 0.583 | L10: 0.88 | M10: 0.73 | N10: 0.798 | O10: 33.508023
A11: rzeszow | B11: val | C11: ft21SGD | D11: pv | E11: 661 | F11: 2767 | G11: 0.675 | H11: 0.49 | I11: 0.568 | J11: 0.529 | K11: 0.357 | L11: 0.664 | M11: 0.482 | N11: 0.559 | O11: 11.878448
A12: rzeszow | B12: val | C12: ariel | D12: solar-panel | E12: 661 | F12: 2767 | G12: 0.834 | H12: 0.718 | I12: 0.772 | J12: 0.759 | K12: 0.501 | L12: 0 | M12: 0 | N12: 0 | O12: 7.8351464
A13: rzeszow | B13: val | C13: pools | D13: solarpanel | E13: 661 | F13: 2767 | G13: 0.606 | H13: 0.387 | I13: 0.472 | J13: 0.43 | K13: 0.275 | L13: 0 | M13: 0 | N13: 0 | O13: 11.028481
... A41: synth_new | B41: test | C41: pools | D41: solarpanel | E41: 114 | F41: 114 | G41: 0.111 | H41: 0.088 | I41: 0.098 | J41: 0.021 | K41: 0.003 | L41: 0 | M41: 0 | N41: 0 | O41: 4.618891
